
Logged in to project, explore it here https://c.app.hopsworks.ai:443/p/1225911
[06/24/25 04:54:39] INFO     üìã Could not list existing feature groups - will create all                                                                                                                                            nodes.py:288
                    INFO     üìã Found 0 existing feature groups                                                                                                                                                                     nodes.py:291
[06/24/25 04:54:40] INFO     üîÑ Creating feature group: personal_information                                                                                                                                                        nodes.py:386
                    INFO        Available columns: ['age_at_injury', 'birth_year']                                                                                                                                                  nodes.py:387
                    WARNING     Missing columns: ['gender']                                                                                                                                                                         nodes.py:389
                    INFO        Data shape: (593471, 4)                                                                                                                                                                             nodes.py:395
                    INFO        üîç Validating data with Great Expectations...                                                                                                                                                       nodes.py:401
                    INFO     Using existing expectation suite: personal_information_expectations                                                                                                                       feature_store_utils.py:42
                    ERROR    Validation failed for personal_information_expectations: Cannot initialize datasource pandas_datasource, error: The given datasource could not be retrieved from the DataContext; please  feature_store_utils.py:92
                             confirm that your configuration is accurate.                                                                                                                                                                       
                    WARNING     ‚ö†Ô∏è  Data validation failed for personal_information, but proceeding...                                                                                                                               nodes.py:4004
                    INFO        üì§ Attempt 1/3                                                                                                                                                                                      nodes.py:416
                    INFO        üì¶ Large dataset detected. Uploading in chunks of 50,000                                                                                                                                            nodes.py:482
                    INFO        üì¶ Uploading 593,471 rows in 12 chunks                                                                                                                                                              nodes.py:492
                    INFO        üì§ Uploading chunk 1/12 (50,000 rows)                                                                                                                                                               nodes.py:498
                    ERROR       ‚ùå Failed to upload chunk 1: Features are not compatible with Feature Group schema:                                                                                                                 nodes.py:514
                              - gender_m (type: 'bigint') is missing from input dataframe.                                                                                                                                                      
                              - birth_year (type: 'double') does not exist in feature group.                                                                                                                                                    
                             Note that feature (or column) names are case insensitive and spaces are automatically replaced with underscores.                                                                                                   
                    WARNING     ‚ö†Ô∏è  Attempt 1 failed: Data upload failed                                                                                                                                                             nodes.py:4667
                    INFO        ‚è≥ Waiting 30 seconds before retry...                                                                                                                                                               nodes.py:470
[06/24/25 04:55:10] INFO        üì§ Attempt 2/3                                                                                                                                                                                      nodes.py:416
                    INFO        üì¶ Large dataset detected. Uploading in chunks of 50,000                                                                                                                                            nodes.py:482
                    INFO        üì¶ Uploading 593,471 rows in 12 chunks                                                                                                                                                              nodes.py:492
                    INFO        üì§ Uploading chunk 1/12 (50,000 rows)                                                                                                                                                               nodes.py:498
                    ERROR       ‚ùå Failed to upload chunk 1: Features are not compatible with Feature Group schema:                                                                                                                 nodes.py:514
                              - gender_m (type: 'bigint') is missing from input dataframe.                                                                                                                                                      
                              - birth_year (type: 'double') does not exist in feature group.                                                                                                                                                    
                             Note that feature (or column) names are case insensitive and spaces are automatically replaced with underscores.                                                                                                   
                    WARNING     ‚ö†Ô∏è  Attempt 2 failed: Data upload failed                                                                                                                                                             nodes.py:4667
                    INFO        ‚è≥ Waiting 60 seconds before retry...                                                                                                                                                               nodes.py:470
[06/24/25 04:56:10] INFO        üì§ Attempt 3/3                                                                                                                                                                                      nodes.py:416
[06/24/25 04:56:11] INFO        üì¶ Large dataset detected. Uploading in chunks of 50,000                                                                                                                                            nodes.py:482
                    INFO        üì¶ Uploading 593,471 rows in 12 chunks                                                                                                                                                              nodes.py:492
                    INFO        üì§ Uploading chunk 1/12 (50,000 rows)                                                                                                                                                               nodes.py:498
                    ERROR       ‚ùå Failed to upload chunk 1: Features are not compatible with Feature Group schema:                                                                                                                 nodes.py:514
                              - gender_m (type: 'bigint') is missing from input dataframe.                                                                                                                                                      
                              - birth_year (type: 'double') does not exist in feature group.                                                                                                                                                    
                             Note that feature (or column) names are case insensitive and spaces are automatically replaced with underscores.                                                                                                   
                    WARNING     ‚ö†Ô∏è  Attempt 3 failed: Data upload failed                                                                                                                                                             nodes.py:4667
                    ERROR    ‚ùå Failed to create: personal_information - All 3 attempts failed. Last error: Data upload failed                                                                                                      nodes.py:343
                    INFO     üîÑ Creating feature group: financial_features                                                                                                                                                          nodes.py:386
                    INFO        Available columns: ['average_weekly_wage', 'number_of_dependents']                                                                                                                                  nodes.py:387
                    INFO        Data shape: (593471, 4)                                                                                                                                                                             nodes.py:395
                    INFO        üîç Validating data with Great Expectations...                                                                                                                                                       nodes.py:401
                    INFO     Using existing expectation suite: financial_features_expectations                                                                                                                         feature_store_utils.py:42
                    ERROR    Validation failed for financial_features_expectations: Cannot initialize datasource pandas_datasource, error: The given datasource could not be retrieved from the DataContext; please    feature_store_utils.py:92
                             confirm that your configuration is accurate.                                                                                                                                                                       
                    WARNING     ‚ö†Ô∏è  Data validation failed for financial_features, but proceeding...                                                                                                                                 nodes.py:4004
                    INFO        üì§ Attempt 1/3                                                                                                                                                                                      nodes.py:416
                    INFO        üì¶ Large dataset detected. Uploading in chunks of 50,000                                                                                                                                            nodes.py:482
                    INFO        üì¶ Uploading 593,471 rows in 12 chunks                                                                                                                                                              nodes.py:492
                    INFO        üì§ Uploading chunk 1/12 (50,000 rows)                                                                                                                                                               nodes.py:498
                    ERROR       ‚ùå Failed to upload chunk 1: Features are not compatible with Feature Group schema:                                                                                                                 nodes.py:514
                              - number_of_dependents (type: 'double') does not exist in feature group.                                                                                                                                          
                             Note that feature (or column) names are case insensitive and spaces are automatically replaced with underscores.                                                                                                   
                    WARNING     ‚ö†Ô∏è  Attempt 1 failed: Data upload failed                                                                                                                                                             nodes.py:4667
                    INFO        ‚è≥ Waiting 30 seconds before retry...                                                                                                                                                               nodes.py:470
[06/24/25 04:56:41] INFO        üì§ Attempt 2/3                                                                                                                                                                                      nodes.py:416
[06/24/25 04:56:42] INFO        üì¶ Large dataset detected. Uploading in chunks of 50,000                                                                                                                                            nodes.py:482
                    INFO        üì¶ Uploading 593,471 rows in 12 chunks                                                                                                                                                              nodes.py:492
                    INFO        üì§ Uploading chunk 1/12 (50,000 rows)                                                                                                                                                               nodes.py:498
                    ERROR       ‚ùå Failed to upload chunk 1: Features are not compatible with Feature Group schema:                                                                                                                 nodes.py:514
                              - number_of_dependents (type: 'double') does not exist in feature group.                                                                                                                                          
                             Note that feature (or column) names are case insensitive and spaces are automatically replaced with underscores.                                                                                                   
                    WARNING     ‚ö†Ô∏è  Attempt 2 failed: Data upload failed                                                                                                                                                             nodes.py:4667
                    INFO        ‚è≥ Waiting 60 seconds before retry...                                                                                                                                                               nodes.py:470
[06/24/25 04:57:42] INFO        üì§ Attempt 3/3                                                                                                                                                                                      nodes.py:416
                    INFO        üì¶ Large dataset detected. Uploading in chunks of 50,000                                                                                                                                            nodes.py:482
                    INFO        üì¶ Uploading 593,471 rows in 12 chunks                                                                                                                                                              nodes.py:492
                    INFO        üì§ Uploading chunk 1/12 (50,000 rows)                                                                                                                                                               nodes.py:498
                    ERROR       ‚ùå Failed to upload chunk 1: Features are not compatible with Feature Group schema:                                                                                                                 nodes.py:514
                              - number_of_dependents (type: 'double') does not exist in feature group.                                                                                                                                          
                             Note that feature (or column) names are case insensitive and spaces are automatically replaced with underscores.                                                                                                   
                    WARNING     ‚ö†Ô∏è  Attempt 3 failed: Data upload failed                                                                                                                                                             nodes.py:4667
                    ERROR    ‚ùå Failed to create: financial_features - All 3 attempts failed. Last error: Data upload failed                                                                                                        nodes.py:343
                    INFO     üîÑ Creating feature group: medical_case_processing                                                                                                                                                     nodes.py:386
                    INFO        Available columns: ['ime_4_count']                                                                                                                                                                  nodes.py:387
                    WARNING     Missing columns: ['attorney_representative', 'alternative_dispute_resolution']                                                                                                                      nodes.py:389
                    INFO        Data shape: (593471, 3)                                                                                                                                                                             nodes.py:395
                    INFO        üîç Validating data with Great Expectations...                                                                                                                                                       nodes.py:401
                    INFO     Using existing expectation suite: medical_case_processing_expectations                                                                                                                    feature_store_utils.py:42
                    ERROR    Validation failed for medical_case_processing_expectations: Cannot initialize datasource pandas_datasource, error: The given datasource could not be retrieved from the DataContext;      feature_store_utils.py:92
                    INFO        üì§ Attempt 1/3                                                                                                                                                                                      nodes.py:416                 
[06/24/25 04:57:43] INFO        üì¶ Large dataset detected. Uploading in chunks of 50,000                                                                                                                                            nodes.py:482                 
                    INFO        üì¶ Uploading 593,471 rows in 12 chunks                                                                                                                                                              nodes.py:492                 
                    INFO        üì§ Uploading chunk 1/12 (50,000 rows)                                                                                                                                                               nodes.py:498                 
                    ERROR       ‚ùå Failed to upload chunk 1: Features are not compatible with Feature Group schema:                                                                                                                 nodes.py:514                 
                              - attorney_representative_y (type: 'bigint') is missing from input dataframe.                                                                                                                                                      
                              - alternative_dispute_resolution_y (type: 'bigint') is missing from input dataframe.                                                                                                                                               
                             Note that feature (or column) names are case insensitive and spaces are automatically replaced with underscores.                                                                                                                    
                    WARNING     ‚ö†Ô∏è  Attempt 1 failed: Data upload failed                                                                                                                                                             nodes.py:467
                    INFO        ‚è≥ Waiting 30 seconds before retry...                                                                                                                                                               nodes.py:470                 
[06/24/25 04:58:13] INFO        üì§ Attempt 2/3                                                                                                                                                                                      nodes.py:416                 
                    INFO        üì¶ Large dataset detected. Uploading in chunks of 50,000                                                                                                                                            nodes.py:482                 
                    INFO        üì¶ Uploading 593,471 rows in 12 chunks                                                                                                                                                              nodes.py:492                 
                    INFO        üì§ Uploading chunk 1/12 (50,000 rows)                                                                                                                                                               nodes.py:498                 
                    ERROR       ‚ùå Failed to upload chunk 1: Features are not compatible with Feature Group schema:                                                                                                                 nodes.py:514                 
                              - attorney_representative_y (type: 'bigint') is missing from input dataframe.                                                                                                                                                      
                              - alternative_dispute_resolution_y (type: 'bigint') is missing from input dataframe.                                                                                                                                               
                             Note that feature (or column) names are case insensitive and spaces are automatically replaced with underscores.                                                                                                                    
                    WARNING     ‚ö†Ô∏è  Attempt 2 failed: Data upload failed                                                                                                                                                             nodes.py:467
                    INFO        ‚è≥ Waiting 60 seconds before retry...                                                                                                                                                               nodes.py:470                 
[06/24/25 04:59:13] INFO        üì§ Attempt 3/3                                                                                                                                                                                                       nodes.py:416
[06/24/25 04:59:14] INFO        üì¶ Large dataset detected. Uploading in chunks of 50,000                                                                                                                                                             nodes.py:482
                    INFO        üì¶ Uploading 593,471 rows in 12 chunks                                                                                                                                                                               nodes.py:492
                    INFO        üì§ Uploading chunk 1/12 (50,000 rows)                                                                                                                                                                                nodes.py:498
                    ERROR       ‚ùå Failed to upload chunk 1: Features are not compatible with Feature Group schema:                                                                                                                                  nodes.py:514
                              - attorney_representative_y (type: 'bigint') is missing from input dataframe.                                                                                                                                                      
                              - alternative_dispute_resolution_y (type: 'bigint') is missing from input dataframe.                                                                                                                                               
                             Note that feature (or column) names are case insensitive and spaces are automatically replaced with underscores.                                                                                                                    
                    WARNING     ‚ö†Ô∏è  Attempt 3 failed: Data upload failed                                                                                                                                                                              nodes.py:467
                    ERROR    ‚ùå Failed to create: medical_case_processing - All 3 attempts failed. Last error: Data upload failed                                                                                                                    nodes.py:343
                    INFO     üîÑ Creating feature group: geographic_administrative                                                                                                                                                                    nodes.py:386
                    INFO        Available columns: ['county_of_injury', 'district_name', 'zip_code']                                                                                                                                                 nodes.py:387
                    INFO        Data shape: (593471, 5)                                                                                                                                                                                              nodes.py:395
                    INFO        üîç Validating data with Great Expectations...                                                                                                                                                                        nodes.py:401
                    INFO     Using existing expectation suite: geographic_administrative_expectations                                                                                                                                   feature_store_utils.py:42
                    ERROR    Validation failed for geographic_administrative_expectations: Cannot initialize datasource pandas_datasource, error: The given datasource could not be retrieved from the DataContext; please confirm that feature_store_utils.py:92
                             your configuration is accurate.                                                                                                                                                                                                     
                    WARNING     ‚ö†Ô∏è  Data validation failed for geographic_administrative, but proceeding...                                                                                                                                           nodes.py:404
                    INFO        üì§ Attempt 1/3                                                                                                                                                                                                       nodes.py:416
                    INFO        üì¶ Large dataset detected. Uploading in chunks of 50,000                                                                                                                                                             nodes.py:482
                    INFO        üì¶ Uploading 593,471 rows in 12 chunks                                                                                                                                                                               nodes.py:492
                    INFO        üì§ Uploading chunk 1/12 (50,000 rows)                                                                                                                                                                                nodes.py:498
                    ERROR       ‚ùå Failed to upload chunk 1: Features are not compatible with Feature Group schema:                                                                                                                                  nodes.py:514
                              - zip_code (type: 'string') does not exist in feature group.                                                                                                                                                                       
                             Note that feature (or column) names are case insensitive and spaces are automatically replaced with underscores.                                                                                                                    
                    WARNING     ‚ö†Ô∏è  Attempt 1 failed: Data upload failed                                                                                                                                                                              nodes.py:46
                                                                                                                                                                                                                                                                67
                    INFO        ‚è≥ Waiting 30 seconds before retry...                                                                                                                                                                                nodes.py:470
[06/24/25 04:59:44] INFO        üì§ Attempt 2/3                                                                                                                                                                                                       nodes.py:416
[06/24/25 04:59:45] INFO        üì¶ Large dataset detected. Uploading in chunks of 50,000                                                                                                                                                             nodes.py:482
                    INFO        üì¶ Uploading 593,471 rows in 12 chunks                                                                                                                                                                               nodes.py:492
                    INFO        üì§ Uploading chunk 1/12 (50,000 rows)                                                                                                                                                                                nodes.py:498
                    ERROR       ‚ùå Failed to upload chunk 1: Features are not compatible with Feature Group schema:                                                                                                                                  nodes.py:514
                              - zip_code (type: 'string') does not exist in feature group.                                                                                                                                                                       
                             Note that feature (or column) names are case insensitive and spaces are automatically replaced with underscores.                                                                                                                    
                    WARNING     ‚ö†Ô∏è  Attempt 2 failed: Data upload failed                                                                                                                                                                              nodes.py:4667
                    INFO        ‚è≥ Waiting 60 seconds before retry...                                                                                                                                                                                nodes.py:470
[06/24/25 05:00:45] INFO        üì§ Attempt 3/3                                                                                                                                                                                                       nodes.py:416
                    INFO        üì¶ Large dataset detected. Uploading in chunks of 50,000                                                                                                                                                             nodes.py:482
                    INFO        üì¶ Uploading 593,471 rows in 12 chunks                                                                                                                                                                               nodes.py:492
                    INFO        üì§ Uploading chunk 1/12 (50,000 rows)                                                                                                                                                                                nodes.py:498
                    ERROR       ‚ùå Failed to upload chunk 1: Features are not compatible with Feature Group schema:                                                                                                                                  nodes.py:514
                              - zip_code (type: 'string') does not exist in feature group.                                                                                                                                                                       
                             Note that feature (or column) names are case insensitive and spaces are automatically replaced with underscores.                                                                                                                    
                    WARNING     ‚ö†Ô∏è  Attempt 3 failed: Data upload failed                                                                                                                                                                              nodes.py:4667
                    ERROR    ‚ùå Failed to create: geographic_administrative - All 3 attempts failed. Last error: Data upload failed                                                                                                                  nodes.py:343
                    INFO     üîÑ Creating feature group: injury_industry_classification                                                                                                                                                               nodes.py:386
                    INFO        Available columns: ['wcio_nature_of_injury_code', 'industry_code', 'wcio_cause_of_injury_code', 'wcio_part_of_body_code']                                                                                            nodes.py:387
                    INFO        Data shape: (593471, 6)                                                                                                                                                                                              nodes.py:395
                    INFO        üîç Validating data with Great Expectations...                                                                                                                                                                        nodes.py:401
                    INFO     Using existing expectation suite: injury_industry_classification_expectations                                                                                                                              feature_store_utils.py:42
                    ERROR    Validation failed for injury_industry_classification_expectations: Cannot initialize datasource pandas_datasource, error: The given datasource could not be retrieved from the DataContext; please confirm feature_store_utils.py:92
                             that your configuration is accurate.                                                                                                                                                                                                
                    WARNING     ‚ö†Ô∏è  Data validation failed for injury_industry_classification, but proceeding...                                                                                                                                      nodes.py:4004
                    INFO        üì§ Attempt 1/3                                                                                                                                                                                                       nodes.py:416
[06/24/25 05:00:46] INFO        üì¶ Large dataset detected. Uploading in chunks of 50,000                                                                                                                                                             nodes.py:482
                    INFO        üì¶ Uploading 593,471 rows in 12 chunks                                                                                                                                                                               nodes.py:492
                    INFO        üì§ Uploading chunk 1/12 (50,000 rows)                                                                                                                                                                                nodes.py:498
                    ERROR       ‚ùå Failed to upload chunk 1: Features are not compatible with Feature Group schema:                                                                                                                                  nodes.py:514
                              - wcio_nature_of_injury_code (expected type: 'double', derived from input: 'string') has the wrong type.                                                                                                                           
                              - industry_code (expected type: 'double', derived from input: 'string') has the wrong type.                                                                                                                                        
                              - wcio_cause_of_injury_code (expected type: 'double', derived from input: 'string') has the wrong type.                                                                                                                            
                              - wcio_part_of_body_code (expected type: 'double', derived from input: 'string') has the wrong type.                                                                                                                               
                             Note that feature (or column) names are case insensitive and spaces are automatically replaced with underscores.                                                                                                                    
                    WARNING     ‚ö†Ô∏è  Attempt 1 failed: Data upload failed                                                                                                                                                                              nodes.py:4667
                    INFO        ‚è≥ Waiting 30 seconds before retry...                                                                                                                                                                                nodes.py:470
[06/24/25 05:01:16] INFO        üì§ Attempt 2/3                                                                                                                                                                                                       nodes.py:416
                    INFO        üì¶ Large dataset detected. Uploading in chunks of 50,000                                                                                                                                                             nodes.py:482
                    INFO        üì¶ Uploading 593,471 rows in 12 chunks                                                                                                                                                                               nodes.py:492
                    INFO        üì§ Uploading chunk 1/12 (50,000 rows)                                                                                                                                                                                nodes.py:498
                    ERROR       ‚ùå Failed to upload chunk 1: Features are not compatible with Feature Group schema:                                                                                                                                  nodes.py:514
                              - wcio_nature_of_injury_code (expected type: 'double', derived from input: 'string') has the wrong type.                                                                                                                           
                              - industry_code (expected type: 'double', derived from input: 'string') has the wrong type.                                                                                                                                        
                              - wcio_cause_of_injury_code (expected type: 'double', derived from input: 'string') has the wrong type.                                                                                                                            
                              - wcio_part_of_body_code (expected type: 'double', derived from input: 'string') has the wrong type.                                                                                                                               
                             Note that feature (or column) names are case insensitive and spaces are automatically replaced with underscores.                                                                                                                    
                    WARNING     ‚ö†Ô∏è  Attempt 2 failed: Data upload failed                                                                                                                                                                              nodes.py:4667
                    INFO        ‚è≥ Waiting 60 seconds before retry...                                                                                                                                                                                nodes.py:470
[06/24/25 05:02:16] INFO        üì§ Attempt 3/3                                                                                                                                                                                                       nodes.py:416
[06/24/25 05:02:17] INFO        üì¶ Large dataset detected. Uploading in chunks of 50,000                                                                                                                                                             nodes.py:482
                    INFO        üì¶ Uploading 593,471 rows in 12 chunks                                                                                                                                                                               nodes.py:492
                    INFO        üì§ Uploading chunk 1/12 (50,000 rows)                                                                                                                                                                                nodes.py:498
                    ERROR       ‚ùå Failed to upload chunk 1: Features are not compatible with Feature Group schema:                                                                                                                                  nodes.py:514
                              - wcio_nature_of_injury_code (expected type: 'double', derived from input: 'string') has the wrong type.                                                                                                                           
                              - industry_code (expected type: 'double', derived from input: 'string') has the wrong type.                                                                                                                                        
                              - wcio_cause_of_injury_code (expected type: 'double', derived from input: 'string') has the wrong type.                                                                                                                            
                              - wcio_part_of_body_code (expected type: 'double', derived from input: 'string') has the wrong type.                                                                                                                               
                             Note that feature (or column) names are case insensitive and spaces are automatically replaced with underscores.                                                                                                                    
                    WARNING     ‚ö†Ô∏è  Attempt 3 failed: Data upload failed                                                                                                                                                                              nodes.py:4667
                    ERROR    ‚ùå Failed to create: injury_industry_classification - All 3 attempts failed. Last error: Data upload failed                                                                                                             nodes.py:343
                    WARNING  ‚è≠Ô∏è  Skipping medical_fee_regions - no columns available                                                                                                                                                                  nodes.py:3220
                    WARNING  ‚è≠Ô∏è  Skipping special_indicators - no columns available                                                                                                                                                                   nodes.py:3220
                    WARNING  ‚è≠Ô∏è  Skipping temporal_features - no columns available                                                                                                                                                                    nodes.py:3220
                    INFO     === SUMMARY ===                                                                                                                                                                                                         nodes.py:361
                    INFO     ‚úÖ Created: 0 feature groups                                                                                                                                                                                            nodes.py:362
                    INFO     ‚ùå Failed: 5 feature groups                                                                                                                                                                                             nodes.py:363
                    INFO     ‚è≠Ô∏è  Skipped: 3 feature groups                                                                                                                                                                                            nodes.py:3664
                    INFO     üîç Used Great Expectations: True                                                                                                                                                                                        nodes.py:365
                    INFO     Saving data to feature_groups_metadata (JSONDataset)...                                                                                                                                                          data_catalog.py:443
                    INFO     Completed node: robust_feature_groups_with_gx                                                                                                                                                                          runner.py:244
                    INFO     Completed 8 out of 15 tasks                                                                                                                                                                                            runner.py:245
                    INFO     Loading data from processed_data (CSVDataset)...                                                                                                                                                                 data_catalog.py:401
[06/24/25 05:02:18] INFO     Loading data from params:group_name (MemoryDataset)...                                                                                                                                                           data_catalog.py:401
                    INFO     Loading data from params:description (MemoryDataset)...                                                                                                                                                          data_catalog.py:401
                    INFO     Loading data from params:feature_descriptions (MemoryDataset)...                                                                                                                                                 data_catalog.py:401
                    INFO     Loading data from params:suite_name (MemoryDataset)...                                                                                                                                                           data_catalog.py:401
                    INFO     Running node: upload_data: upload_data() -> None                                                                                                                                                                         node.py:367
[06/24/25 05:02:19] INFO     Prepared data for upload. Shape: (593471, 34)                                                                                                                                                                            nodes.py:64
                    INFO     Data types: {'index': dtype('int64'), 'Accident Date': string, 'Age at Injury': dtype('float64'), 'Alternative Dispute Resolution': string, 'Assembly Date': string, 'Attorney/Representative': string, 'Average Weekly  nodes.py:65
                             Wage': dtype('float64'), 'Birth Year': dtype('float64'), 'C-2 Date': string, 'C-3 Date': string, 'Carrier Name': string, 'Carrier Type': string, 'Claim Identifier': dtype('int64'), 'Claim Injury Type': string,                   
                             'County of Injury': dtype('float64'), 'COVID-19 Indicator': string, 'District Name': string, 'First Hearing Date': string, 'Gender': string, 'IME-4 Count': dtype('float64'), 'Industry Code': dtype('float64'),                    
                             'Industry Code Description': string, 'Medical Fee Region': string, 'WCIO Cause of Injury Code': dtype('float64'), 'WCIO Cause of Injury Description': string, 'WCIO Nature of Injury Code': dtype('float64'), 'WCIO                 
                             Nature of Injury Description': string, 'WCIO Part Of Body Code': dtype('float64'), 'WCIO Part Of Body Description': string, 'Zip Code': string, 'Agreement Reached': dtype('float64'), 'WCB Decision': string, 'Number              
                             of Dependents': dtype('float64'), 'datetime': dtype('<M8')}                                                                                                                                                                         
Connection closed.

Logged in to project, explore it here https://c.app.hopsworks.ai:443/p/1225911
[06/24/25 05:02:22] ERROR    Node upload_data: upload_data() -> None failed with error:                                                                                                                                                               node.py:392
                             Metadata operation error: (url: https://c.app.hopsworks.ai/hopsworks-api/api/project/1225911/featurestores/1212515/featuregroups). Server response:                                                                                 
                             HTTP code: 400, HTTP reason: Bad Request, body: b'{"errorCode":270040,"usrMsg":", the provided feature name attorney/representative is invalid. Feature names can only contain lower case characters, numbers and                   
                             underscores, have to start with a letter and cannot be longer than 63 characters or empty.","errorMsg":"Illegal feature name"}', error code: 270040, error msg: Illegal feature name, user msg: , the provided feature              
                             name attorney/representative is invalid. Feature names can only contain lower case characters, numbers and underscores, have to start with a letter and cannot be longer than 63 characters or empty.                               
                    WARNING  There are 7 nodes that have not run.                                                                                                                                                                                   runner.py:338
                             You can resume the pipeline run from the nearest nodes with persisted inputs by adding the following argument to your previous command:                                                                                             
                               --from-nodes "combine_feature_selection_node,upload_data,validate_feature_store_setup"                                                                                                                                            
‚ï≠‚îÄ‚îÄ‚îÄ‚îÄ‚îÄ‚îÄ‚îÄ‚îÄ‚îÄ‚îÄ‚îÄ‚îÄ‚îÄ‚îÄ‚îÄ‚îÄ‚îÄ‚îÄ‚îÄ‚îÄ‚îÄ‚îÄ‚îÄ‚îÄ‚îÄ‚îÄ‚îÄ‚îÄ‚îÄ‚îÄ‚îÄ Traceback (most recent call last) ‚îÄ‚îÄ‚îÄ‚îÄ‚îÄ‚îÄ‚îÄ‚îÄ‚îÄ‚îÄ‚îÄ‚îÄ‚îÄ‚îÄ‚îÄ‚îÄ‚îÄ‚îÄ‚îÄ‚îÄ‚îÄ‚îÄ‚îÄ‚îÄ‚îÄ‚îÄ‚îÄ‚îÄ‚îÄ‚îÄ‚îÄ‚îÄ‚ïÆ
‚îÇ in _run_module_as_main:198                                                                       ‚îÇ
‚îÇ in _run_code:88                                                                                  ‚îÇ
‚îÇ                                                                                                  ‚îÇ
‚îÇ in <module>:7                                                                                    ‚îÇ
‚îÇ                                                                                                  ‚îÇ
‚îÇ E:\Master                                                                                        ‚îÇ
‚îÇ Projects\MLFlow-in-Claim-Injury-Prediction\env\Lib\site-packages\kedro\framework\cli\cli.py:263  ‚îÇ
‚îÇ in main                                                                                          ‚îÇ
‚îÇ                                                                                                  ‚îÇ
‚îÇ   260 ‚îÇ   cli_collection = KedroCLI(                                                             ‚îÇ
‚îÇ   261 ‚îÇ   ‚îÇ   project_path=_find_kedro_project(Path.cwd()) or Path.cwd()                         ‚îÇ
‚îÇ   262 ‚îÇ   )                                                                                      ‚îÇ
‚îÇ ‚ù± 263 ‚îÇ   cli_collection()                                                                       ‚îÇ
‚îÇ   264                                                                                            ‚îÇ
‚îÇ                                                                                                  ‚îÇ
‚îÇ E:\Master Projects\MLFlow-in-Claim-Injury-Prediction\env\Lib\site-packages\click\core.py:1442 in ‚îÇ
‚îÇ __call__                                                                                         ‚îÇ
‚îÇ                                                                                                  ‚îÇ
‚îÇ E:\Master                                                                                        ‚îÇ
‚îÇ Projects\MLFlow-in-Claim-Injury-Prediction\env\Lib\site-packages\kedro\framework\cli\cli.py:163  ‚îÇ
‚îÇ in main                                                                                          ‚îÇ
‚îÇ                                                                                                  ‚îÇ
‚îÇ   160 ‚îÇ   ‚îÇ   )                                                                                  ‚îÇ
‚îÇ   161 ‚îÇ   ‚îÇ                                                                                      ‚îÇ
‚îÇ   162 ‚îÇ   ‚îÇ   try:                                                                               ‚îÇ
‚îÇ ‚ù± 163 ‚îÇ   ‚îÇ   ‚îÇ   super().main(                                                                  ‚îÇ
‚îÇ   164 ‚îÇ   ‚îÇ   ‚îÇ   ‚îÇ   args=args,                                                                 ‚îÇ
‚îÇ   165 ‚îÇ   ‚îÇ   ‚îÇ   ‚îÇ   prog_name=prog_name,                                                       ‚îÇ
‚îÇ   166 ‚îÇ   ‚îÇ   ‚îÇ   ‚îÇ   complete_var=complete_var,                                                 ‚îÇ
‚îÇ                                                                                                  ‚îÇ
‚îÇ E:\Master Projects\MLFlow-in-Claim-Injury-Prediction\env\Lib\site-packages\click\core.py:1363 in ‚îÇ
‚îÇ main                                                                                             ‚îÇ
‚îÇ                                                                                                  ‚îÇ
‚îÇ E:\Master Projects\MLFlow-in-Claim-Injury-Prediction\env\Lib\site-packages\click\core.py:1830 in ‚îÇ
‚îÇ invoke                                                                                           ‚îÇ
‚îÇ                                                                                                  ‚îÇ
‚îÇ E:\Master Projects\MLFlow-in-Claim-Injury-Prediction\env\Lib\site-packages\click\core.py:1226 in ‚îÇ
‚îÇ invoke                                                                                           ‚îÇ
‚îÇ                                                                                                  ‚îÇ
‚îÇ E:\Master Projects\MLFlow-in-Claim-Injury-Prediction\env\Lib\site-packages\click\core.py:794 in  ‚îÇ
‚îÇ invoke                                                                                           ‚îÇ
‚îÇ                                                                                                  ‚îÇ
‚îÇ E:\Master                                                                                        ‚îÇ
‚îÇ Projects\MLFlow-in-Claim-Injury-Prediction\env\Lib\site-packages\kedro\framework\cli\project.py: ‚îÇ
‚îÇ 229 in run                                                                                       ‚îÇ
‚îÇ                                                                                                  ‚îÇ
‚îÇ   226 ‚îÇ   with KedroSession.create(                                                              ‚îÇ
‚îÇ   227 ‚îÇ   ‚îÇ   env=env, conf_source=conf_source, extra_params=params                              ‚îÇ
‚îÇ   228 ‚îÇ   ) as session:                                                                          ‚îÇ
‚îÇ ‚ù± 229 ‚îÇ   ‚îÇ   return session.run(                                                                ‚îÇ
‚îÇ   230 ‚îÇ   ‚îÇ   ‚îÇ   tags=tuple_tags,                                                               ‚îÇ
‚îÇ   231 ‚îÇ   ‚îÇ   ‚îÇ   runner=runner_obj(is_async=is_async),                                          ‚îÇ
‚îÇ   232 ‚îÇ   ‚îÇ   ‚îÇ   node_names=tuple_node_names,                                                   ‚îÇ
‚îÇ                                                                                                  ‚îÇ
‚îÇ E:\Master                                                                                        ‚îÇ
‚îÇ Projects\MLFlow-in-Claim-Injury-Prediction\env\Lib\site-packages\kedro\framework\session\session ‚îÇ
‚îÇ .py:399 in run                                                                                   ‚îÇ
‚îÇ                                                                                                  ‚îÇ
‚îÇ   396 ‚îÇ   ‚îÇ   ‚îÇ   run_params=record_data, pipeline=filtered_pipeline, catalog=catalog            ‚îÇ
‚îÇ   397 ‚îÇ   ‚îÇ   )                                                                                  ‚îÇ
‚îÇ   398 ‚îÇ   ‚îÇ   try:                                                                               ‚îÇ
‚îÇ ‚ù± 399 ‚îÇ   ‚îÇ   ‚îÇ   run_result = runner.run(                                                       ‚îÇ
‚îÇ   400 ‚îÇ   ‚îÇ   ‚îÇ   ‚îÇ   filtered_pipeline, catalog, hook_manager, session_id                       ‚îÇ
‚îÇ   401 ‚îÇ   ‚îÇ   ‚îÇ   )                                                                              ‚îÇ
‚îÇ   402 ‚îÇ   ‚îÇ   ‚îÇ   self._run_called = True                                                        ‚îÇ
‚îÇ                                                                                                  ‚îÇ
‚îÇ E:\Master                                                                                        ‚îÇ
‚îÇ Projects\MLFlow-in-Claim-Injury-Prediction\env\Lib\site-packages\kedro\runner\runner.py:129 in   ‚îÇ
‚îÇ run                                                                                              ‚îÇ
‚îÇ                                                                                                  ‚îÇ
‚îÇ   126 ‚îÇ   ‚îÇ   ‚îÇ   ‚îÇ   "Asynchronous mode is enabled for loading and saving data"                 ‚îÇ
‚îÇ   127 ‚îÇ   ‚îÇ   ‚îÇ   )                                                                              ‚îÇ
‚îÇ   128 ‚îÇ   ‚îÇ                                                                                      ‚îÇ
‚îÇ ‚ù± 129 ‚îÇ   ‚îÇ   self._run(pipeline, catalog, hook_or_null_manager, session_id)  # type: ignore[a   ‚îÇ
‚îÇ   130 ‚îÇ   ‚îÇ                                                                                      ‚îÇ
‚îÇ   131 ‚îÇ   ‚îÇ   self._logger.info("Pipeline execution completed successfully.")                    ‚îÇ
‚îÇ   132                                                                                            ‚îÇ
‚îÇ                                                                                                  ‚îÇ
‚îÇ E:\Master                                                                                        ‚îÇ
‚îÇ Projects\MLFlow-in-Claim-Injury-Prediction\env\Lib\site-packages\kedro\runner\sequential_runner. ‚îÇ
‚îÇ py:72 in _run                                                                                    ‚îÇ
‚îÇ                                                                                                  ‚îÇ
‚îÇ   69 ‚îÇ   ‚îÇ   ‚îÇ   ‚îÇ   "Using synchronous mode for loading and saving data. Use the --async fla    ‚îÇ
‚îÇ   70 ‚îÇ   ‚îÇ   ‚îÇ   ‚îÇ   "for potential performance gains. https://docs.kedro.org/en/stable/nodes    ‚îÇ
‚îÇ   71 ‚îÇ   ‚îÇ   ‚îÇ   )                                                                               ‚îÇ
‚îÇ ‚ù± 72 ‚îÇ   ‚îÇ   super()._run(                                                                       ‚îÇ
‚îÇ   73 ‚îÇ   ‚îÇ   ‚îÇ   pipeline=pipeline,                                                              ‚îÇ
‚îÇ   74 ‚îÇ   ‚îÇ   ‚îÇ   catalog=catalog,                                                                ‚îÇ
‚îÇ   75 ‚îÇ   ‚îÇ   ‚îÇ   hook_manager=hook_manager,                                                      ‚îÇ
‚îÇ                                                                                                  ‚îÇ
‚îÇ E:\Master                                                                                        ‚îÇ
‚îÇ Projects\MLFlow-in-Claim-Injury-Prediction\env\Lib\site-packages\kedro\runner\runner.py:239 in   ‚îÇ
‚îÇ _run                                                                                             ‚îÇ
‚îÇ                                                                                                  ‚îÇ
‚îÇ   236 ‚îÇ   ‚îÇ   ‚îÇ   ‚îÇ   ‚îÇ   ‚îÇ   hook_manager=hook_manager,                                         ‚îÇ
‚îÇ   237 ‚îÇ   ‚îÇ   ‚îÇ   ‚îÇ   ‚îÇ   ‚îÇ   is_async=self._is_async,                                           ‚îÇ
‚îÇ   238 ‚îÇ   ‚îÇ   ‚îÇ   ‚îÇ   ‚îÇ   ‚îÇ   session_id=session_id,                                             ‚îÇ
‚îÇ ‚ù± 239 ‚îÇ   ‚îÇ   ‚îÇ   ‚îÇ   ‚îÇ   ).execute()                                                            ‚îÇ
‚îÇ   240 ‚îÇ   ‚îÇ   ‚îÇ   ‚îÇ   ‚îÇ   done_nodes.add(node)                                                   ‚îÇ
‚îÇ   241 ‚îÇ   ‚îÇ   ‚îÇ   ‚îÇ   except Exception:                                                          ‚îÇ
‚îÇ   242 ‚îÇ   ‚îÇ   ‚îÇ   ‚îÇ   ‚îÇ   self._suggest_resume_scenario(pipeline, done_nodes, catalog)           ‚îÇ
‚îÇ                                                                                                  ‚îÇ
‚îÇ E:\Master                                                                                        ‚îÇ
‚îÇ Projects\MLFlow-in-Claim-Injury-Prediction\env\Lib\site-packages\kedro\runner\task.py:88 in      ‚îÇ
‚îÇ execute                                                                                          ‚îÇ
‚îÇ                                                                                                  ‚îÇ
‚îÇ    85 ‚îÇ   ‚îÇ   ‚îÇ   ‚îÇ   self.session_id,                                                           ‚îÇ
‚îÇ    86 ‚îÇ   ‚îÇ   ‚îÇ   )                                                                              ‚îÇ
‚îÇ    87 ‚îÇ   ‚îÇ   else:                                                                              ‚îÇ
‚îÇ ‚ù±  88 ‚îÇ   ‚îÇ   ‚îÇ   node = self._run_node_sequential(                                              ‚îÇ
‚îÇ    89 ‚îÇ   ‚îÇ   ‚îÇ   ‚îÇ   self.node,                                                                 ‚îÇ
‚îÇ    90 ‚îÇ   ‚îÇ   ‚îÇ   ‚îÇ   self.catalog,                                                              ‚îÇ
‚îÇ    91 ‚îÇ   ‚îÇ   ‚îÇ   ‚îÇ   self.hook_manager,  # type: ignore[arg-type]                               ‚îÇ
‚îÇ                                                                                                  ‚îÇ
‚îÇ E:\Master                                                                                        ‚îÇ
‚îÇ Projects\MLFlow-in-Claim-Injury-Prediction\env\Lib\site-packages\kedro\runner\task.py:164 in     ‚îÇ
‚îÇ _run_node_sequential                                                                             ‚îÇ
‚îÇ                                                                                                  ‚îÇ
‚îÇ   161 ‚îÇ   ‚îÇ   )                                                                                  ‚îÇ
‚îÇ   162 ‚îÇ   ‚îÇ   inputs.update(additional_inputs)                                                   ‚îÇ
‚îÇ   163 ‚îÇ   ‚îÇ                                                                                      ‚îÇ
‚îÇ ‚ù± 164 ‚îÇ   ‚îÇ   outputs = self._call_node_run(                                                     ‚îÇ
‚îÇ   165 ‚îÇ   ‚îÇ   ‚îÇ   node, catalog, inputs, is_async, hook_manager, session_id=session_id           ‚îÇ
‚îÇ   166 ‚îÇ   ‚îÇ   )                                                                                  ‚îÇ
‚îÇ   167                                                                                            ‚îÇ
‚îÇ                                                                                                  ‚îÇ
‚îÇ E:\Master                                                                                        ‚îÇ
‚îÇ Projects\MLFlow-in-Claim-Injury-Prediction\env\Lib\site-packages\kedro\runner\task.py:308 in     ‚îÇ
‚îÇ _call_node_run                                                                                   ‚îÇ
‚îÇ                                                                                                  ‚îÇ
‚îÇ   305 ‚îÇ   ‚îÇ   ‚îÇ   ‚îÇ   is_async=is_async,                                                         ‚îÇ
‚îÇ   306 ‚îÇ   ‚îÇ   ‚îÇ   ‚îÇ   session_id=session_id,                                                     ‚îÇ
‚îÇ   307 ‚îÇ   ‚îÇ   ‚îÇ   )                                                                              ‚îÇ
‚îÇ ‚ù± 308 ‚îÇ   ‚îÇ   ‚îÇ   raise exc                                                                      ‚îÇ
‚îÇ   309 ‚îÇ   ‚îÇ   hook_manager.hook.after_node_run(                                                  ‚îÇ
‚îÇ   310 ‚îÇ   ‚îÇ   ‚îÇ   node=node,                                                                     ‚îÇ
‚îÇ   311 ‚îÇ   ‚îÇ   ‚îÇ   catalog=catalog,                                                               ‚îÇ
‚îÇ                                                                                                  ‚îÇ
‚îÇ E:\Master                                                                                        ‚îÇ
‚îÇ Projects\MLFlow-in-Claim-Injury-Prediction\env\Lib\site-packages\kedro\runner\task.py:298 in     ‚îÇ
‚îÇ _call_node_run                                                                                   ‚îÇ
‚îÇ                                                                                                  ‚îÇ
‚îÇ   295 ‚îÇ   ‚îÇ   session_id: str | None = None,                                                     ‚îÇ
‚îÇ   296 ‚îÇ   ) -> dict[str, Any]:                                                                   ‚îÇ
‚îÇ   297 ‚îÇ   ‚îÇ   try:                                                                               ‚îÇ
‚îÇ ‚ù± 298 ‚îÇ   ‚îÇ   ‚îÇ   outputs = node.run(inputs)                                                     ‚îÇ
‚îÇ   299 ‚îÇ   ‚îÇ   except Exception as exc:                                                           ‚îÇ
‚îÇ   300 ‚îÇ   ‚îÇ   ‚îÇ   hook_manager.hook.on_node_error(                                               ‚îÇ
‚îÇ   301 ‚îÇ   ‚îÇ   ‚îÇ   ‚îÇ   error=exc,                                                                 ‚îÇ
‚îÇ                                                                                                  ‚îÇ
‚îÇ E:\Master                                                                                        ‚îÇ
‚îÇ Projects\MLFlow-in-Claim-Injury-Prediction\env\Lib\site-packages\kedro\pipeline\node.py:398 in   ‚îÇ
‚îÇ run                                                                                              ‚îÇ
‚îÇ                                                                                                  ‚îÇ
‚îÇ   395 ‚îÇ   ‚îÇ   ‚îÇ   ‚îÇ   str(exc),                                                                  ‚îÇ
‚îÇ   396 ‚îÇ   ‚îÇ   ‚îÇ   ‚îÇ   extra={"markup": True},                                                    ‚îÇ
‚îÇ   397 ‚îÇ   ‚îÇ   ‚îÇ   )                                                                              ‚îÇ
‚îÇ ‚ù± 398 ‚îÇ   ‚îÇ   ‚îÇ   raise exc                                                                      ‚îÇ
‚îÇ   399 ‚îÇ                                                                                          ‚îÇ
‚îÇ   400 ‚îÇ   def _run_with_no_inputs(self, inputs: dict[str, Any]) -> Any:                          ‚îÇ
‚îÇ   401 ‚îÇ   ‚îÇ   if inputs:                                                                         ‚îÇ
‚îÇ                                                                                                  ‚îÇ
‚îÇ E:\Master                                                                                        ‚îÇ
‚îÇ Projects\MLFlow-in-Claim-Injury-Prediction\env\Lib\site-packages\kedro\pipeline\node.py:384 in   ‚îÇ
‚îÇ run                                                                                              ‚îÇ
‚îÇ                                                                                                  ‚îÇ
‚îÇ   381 ‚îÇ   ‚îÇ   ‚îÇ   elif isinstance(self._inputs, str):                                            ‚îÇ
‚îÇ   382 ‚îÇ   ‚îÇ   ‚îÇ   ‚îÇ   outputs = self._run_with_one_input(inputs, self._inputs)                   ‚îÇ
‚îÇ   383 ‚îÇ   ‚îÇ   ‚îÇ   elif isinstance(self._inputs, list):                                           ‚îÇ
‚îÇ ‚ù± 384 ‚îÇ   ‚îÇ   ‚îÇ   ‚îÇ   outputs = self._run_with_list(inputs, self._inputs)                        ‚îÇ
‚îÇ   385 ‚îÇ   ‚îÇ   ‚îÇ   elif isinstance(self._inputs, dict):                                           ‚îÇ
‚îÇ   386 ‚îÇ   ‚îÇ   ‚îÇ   ‚îÇ   outputs = self._run_with_dict(inputs, self._inputs)                        ‚îÇ
‚îÇ   387                                                                                            ‚îÇ
‚îÇ                                                                                                  ‚îÇ
‚îÇ E:\Master                                                                                        ‚îÇ
‚îÇ Projects\MLFlow-in-Claim-Injury-Prediction\env\Lib\site-packages\kedro\pipeline\node.py:429 in   ‚îÇ
‚îÇ _run_with_list                                                                                   ‚îÇ
‚îÇ                                                                                                  ‚îÇ
‚îÇ   426 ‚îÇ   ‚îÇ   ‚îÇ   ‚îÇ   f"{sorted(inputs.keys())}."                                                ‚îÇ
‚îÇ   427 ‚îÇ   ‚îÇ   ‚îÇ   )                                                                              ‚îÇ
‚îÇ   428 ‚îÇ   ‚îÇ   # Ensure the function gets the inputs in the correct order                         ‚îÇ
‚îÇ ‚ù± 429 ‚îÇ   ‚îÇ   return self._func(*(inputs[item] for item in node_inputs))                         ‚îÇ
‚îÇ   430 ‚îÇ                                                                                          ‚îÇ
‚îÇ   431 ‚îÇ   def _run_with_dict(                                                                    ‚îÇ
‚îÇ   432 ‚îÇ   ‚îÇ   self, inputs: dict[str, Any], node_inputs: dict[str, str]                          ‚îÇ
‚îÇ                                                                                                  ‚îÇ
‚îÇ E:\Master                                                                                        ‚îÇ
‚îÇ Projects\MLFlow-in-Claim-Injury-Prediction\src\mlflow_in_claim_injury_prediction\pipelines\data_ ‚îÇ
‚îÇ upload\nodes.py:70 in upload_data                                                                ‚îÇ
‚îÇ                                                                                                  ‚îÇ
‚îÇ   67 ‚îÇ   settings_store = read_credentials()["SETTINGS_STORE"]                                   ‚îÇ
‚îÇ   68 ‚îÇ   suite = load_expectation_suite(suite_name)                                              ‚îÇ
‚îÇ   69 ‚îÇ                                                                                           ‚îÇ
‚îÇ ‚ù± 70 ‚îÇ   to_feature_store(                                                                       ‚îÇ
‚îÇ   71 ‚îÇ   ‚îÇ   data=upload_df,                                                                     ‚îÇ
‚îÇ   72 ‚îÇ   ‚îÇ   group_name=group_name,                                                              ‚îÇ
‚îÇ   73 ‚îÇ   ‚îÇ   feature_group_version=1,                                                            ‚îÇ
‚îÇ                                                                                                  ‚îÇ
‚îÇ E:\Master                                                                                        ‚îÇ
‚îÇ Projects\MLFlow-in-Claim-Injury-Prediction\src\mlflow_in_claim_injury_prediction\pipelines\data_ ‚îÇ
‚îÇ upload\utils.py:108 in to_feature_store                                                          ‚îÇ
‚îÇ                                                                                                  ‚îÇ
‚îÇ   105 ‚îÇ   # Upload data.                                                                         ‚îÇ
‚îÇ   106 ‚îÇ   # NOTE: The overwrite parameter is set to False to avoid overwriting the data.         ‚îÇ
‚îÇ   107 ‚îÇ   # instead, the data is appended to the feature group.                                  ‚îÇ
‚îÇ ‚ù± 108 ‚îÇ   object_feature_group.insert(                                                           ‚îÇ
‚îÇ   109 ‚îÇ   ‚îÇ   features=data,                                                                     ‚îÇ
‚îÇ   110 ‚îÇ   ‚îÇ   overwrite=False,                                                                   ‚îÇ
‚îÇ   111 ‚îÇ   ‚îÇ   write_options={                                                                    ‚îÇ
‚îÇ                                                                                                  ‚îÇ
‚îÇ E:\Master                                                                                        ‚îÇ
‚îÇ Projects\MLFlow-in-Claim-Injury-Prediction\env\Lib\site-packages\hsfs\feature_group.py:3014 in   ‚îÇ
‚îÇ insert                                                                                           ‚îÇ
‚îÇ                                                                                                  ‚îÇ
‚îÇ   3011 ‚îÇ   ‚îÇ   if not self._id and self._offline_backfill_every_hr is not None:                  ‚îÇ
‚îÇ   3012 ‚îÇ   ‚îÇ   ‚îÇ   write_options["offline_backfill_every_hr"] = self._offline_backfill_every_hr  ‚îÇ
‚îÇ   3013 ‚îÇ   ‚îÇ                                                                                     ‚îÇ
‚îÇ ‚ù± 3014 ‚îÇ   ‚îÇ   job, ge_report = self._feature_group_engine.insert(                               ‚îÇ
‚îÇ   3015 ‚îÇ   ‚îÇ   ‚îÇ   self,                                                                         ‚îÇ
‚îÇ   3016 ‚îÇ   ‚îÇ   ‚îÇ   feature_dataframe=feature_dataframe,                                          ‚îÇ
‚îÇ   3017 ‚îÇ   ‚îÇ   ‚îÇ   overwrite=overwrite,                                                          ‚îÇ
‚îÇ                                                                                                  ‚îÇ
‚îÇ E:\Master                                                                                        ‚îÇ
‚îÇ Projects\MLFlow-in-Claim-Injury-Prediction\env\Lib\site-packages\hsfs\core\feature_group_engine. ‚îÇ
‚îÇ py:183 in insert                                                                                 ‚îÇ
‚îÇ                                                                                                  ‚îÇ
‚îÇ   180 ‚îÇ   ‚îÇ                                                                                      ‚îÇ
‚îÇ   181 ‚îÇ   ‚îÇ   if not feature_group._id:                                                          ‚îÇ
‚îÇ   182 ‚îÇ   ‚îÇ   ‚îÇ   # only save metadata if feature group does not exist                           ‚îÇ
‚îÇ ‚ù± 183 ‚îÇ   ‚îÇ   ‚îÇ   self.save_feature_group_metadata(                                              ‚îÇ
‚îÇ   184 ‚îÇ   ‚îÇ   ‚îÇ   ‚îÇ   feature_group, dataframe_features, write_options                           ‚îÇ
‚îÇ   185 ‚îÇ   ‚îÇ   ‚îÇ   )                                                                              ‚îÇ
‚îÇ   186 ‚îÇ   ‚îÇ   else:                                                                              ‚îÇ
‚îÇ                                                                                                  ‚îÇ
‚îÇ E:\Master                                                                                        ‚îÇ
‚îÇ Projects\MLFlow-in-Claim-Injury-Prediction\env\Lib\site-packages\hsfs\core\feature_group_engine. ‚îÇ
‚îÇ py:497 in save_feature_group_metadata                                                            ‚îÇ
‚îÇ                                                                                                  ‚îÇ
‚îÇ   494 ‚îÇ   ‚îÇ   ‚îÇ   ‚îÇ   _write_options, _spark_options                                             ‚îÇ
‚îÇ   495 ‚îÇ   ‚îÇ   ‚îÇ   )                                                                              ‚îÇ
‚îÇ   496 ‚îÇ   ‚îÇ                                                                                      ‚îÇ
‚îÇ ‚ù± 497 ‚îÇ   ‚îÇ   self._feature_group_api.save(feature_group)                                        ‚îÇ
‚îÇ   498 ‚îÇ   ‚îÇ   print(                                                                             ‚îÇ
‚îÇ   499 ‚îÇ   ‚îÇ   ‚îÇ   "Feature Group created successfully, explore it at \n"                         ‚îÇ
‚îÇ   500 ‚îÇ   ‚îÇ   ‚îÇ   + util.get_feature_group_url(                                                  ‚îÇ
‚îÇ                                                                                                  ‚îÇ
‚îÇ E:\Master                                                                                        ‚îÇ
‚îÇ Projects\MLFlow-in-Claim-Injury-Prediction\env\Lib\site-packages\hsfs\core\feature_group_api.py: ‚îÇ
‚îÇ 65 in save                                                                                       ‚îÇ
‚îÇ                                                                                                  ‚îÇ
‚îÇ    62 ‚îÇ   ‚îÇ   }                                                                                  ‚îÇ
‚îÇ    63 ‚îÇ   ‚îÇ   headers = {"content-type": "application/json"}                                     ‚îÇ
‚îÇ    64 ‚îÇ   ‚îÇ   feature_group_object = feature_group_instance.update_from_response_json(           ‚îÇ
‚îÇ ‚ù±  65 ‚îÇ   ‚îÇ   ‚îÇ   _client._send_request(                                                         ‚îÇ
‚îÇ    66 ‚îÇ   ‚îÇ   ‚îÇ   ‚îÇ   "POST",                                                                    ‚îÇ
‚îÇ    67 ‚îÇ   ‚îÇ   ‚îÇ   ‚îÇ   path_params,                                                               ‚îÇ
‚îÇ    68 ‚îÇ   ‚îÇ   ‚îÇ   ‚îÇ   headers=headers,                                                           ‚îÇ
‚îÇ                                                                                                  ‚îÇ
‚îÇ E:\Master                                                                                        ‚îÇ
‚îÇ Projects\MLFlow-in-Claim-Injury-Prediction\env\Lib\site-packages\hopsworks_common\decorators.py: ‚îÇ
‚îÇ 48 in if_connected                                                                               ‚îÇ
‚îÇ                                                                                                  ‚îÇ
‚îÇ    45 ‚îÇ   def if_connected(inst, *args, **kwargs):                                               ‚îÇ
‚îÇ    46 ‚îÇ   ‚îÇ   if not inst._connected:                                                            ‚îÇ
‚îÇ    47 ‚îÇ   ‚îÇ   ‚îÇ   raise NoHopsworksConnectionError                                               ‚îÇ
‚îÇ ‚ù±  48 ‚îÇ   ‚îÇ   return fn(inst, *args, **kwargs)                                                   ‚îÇ
‚îÇ    49 ‚îÇ                                                                                          ‚îÇ
‚îÇ    50 ‚îÇ   return if_connected                                                                    ‚îÇ
‚îÇ    51                                                                                            ‚îÇ
‚îÇ                                                                                                  ‚îÇ
‚îÇ E:\Master                                                                                        ‚îÇ
‚îÇ Projects\MLFlow-in-Claim-Injury-Prediction\env\Lib\site-packages\hopsworks_common\client\base.py ‚îÇ
‚îÇ :186 in _send_request                                                                            ‚îÇ
‚îÇ                                                                                                  ‚îÇ
‚îÇ   183 ‚îÇ   ‚îÇ   ‚îÇ   )                                                                              ‚îÇ
‚îÇ   184 ‚îÇ   ‚îÇ                                                                                      ‚îÇ
‚îÇ   185 ‚îÇ   ‚îÇ   if response.status_code // 100 != 2:                                               ‚îÇ
‚îÇ ‚ù± 186 ‚îÇ   ‚îÇ   ‚îÇ   raise exceptions.RestAPIError(url, response)                                   ‚îÇ
‚îÇ   187 ‚îÇ   ‚îÇ                                                                                      ‚îÇ
‚îÇ   188 ‚îÇ   ‚îÇ   if stream:                                                                         ‚îÇ
‚îÇ   189 ‚îÇ   ‚îÇ   ‚îÇ   return response                                                                ‚îÇ
‚ï∞‚îÄ‚îÄ‚îÄ‚îÄ‚îÄ‚îÄ‚îÄ‚îÄ‚îÄ‚îÄ‚îÄ‚îÄ‚îÄ‚îÄ‚îÄ‚îÄ‚îÄ‚îÄ‚îÄ‚îÄ‚îÄ‚îÄ‚îÄ‚îÄ‚îÄ‚îÄ‚îÄ‚îÄ‚îÄ‚îÄ‚îÄ‚îÄ‚îÄ‚îÄ‚îÄ‚îÄ‚îÄ‚îÄ‚îÄ‚îÄ‚îÄ‚îÄ‚îÄ‚îÄ‚îÄ‚îÄ‚îÄ‚îÄ‚îÄ‚îÄ‚îÄ‚îÄ‚îÄ‚îÄ‚îÄ‚îÄ‚îÄ‚îÄ‚îÄ‚îÄ‚îÄ‚îÄ‚îÄ‚îÄ‚îÄ‚îÄ‚îÄ‚îÄ‚îÄ‚îÄ‚îÄ‚îÄ‚îÄ‚îÄ‚îÄ‚îÄ‚îÄ‚îÄ‚îÄ‚îÄ‚îÄ‚îÄ‚îÄ‚îÄ‚îÄ‚îÄ‚îÄ‚îÄ‚îÄ‚îÄ‚îÄ‚îÄ‚îÄ‚îÄ‚îÄ‚îÄ‚îÄ‚îÄ‚ïØ
RestAPIError: Metadata operation error: (url: https://c.app.hopsworks.ai/hopsworks-api/api/project/1225911/featurestores/1212515/featuregroups). Server response:
HTTP code: 400, HTTP reason: Bad Request, body: b'{"errorCode":270040,"usrMsg":", the provided feature name attorney/representative is invalid. Feature names can only contain lower case characters, numbers and underscores, have to start with a letter and   
cannot be longer than 63 characters or empty.","errorMsg":"Illegal feature name"}', error code: 270040, error msg: Illegal feature name, user msg: , the provided feature name attorney/representative is invalid. Feature names can only contain lower case     
characters, numbers and underscores, have to start with a letter and cannot be longer than 63 characters or empty.
Connection closed.